<?xml version="1.0" encoding="UTF-8"?>
<testng-results skipped="2" failed="1" ignored="0" total="3" passed="0">
  <reporter-output>
  </reporter-output>
  <suite name="Default suite" duration-ms="114" started-at="2019-11-01T08:25:29Z" finished-at="2019-11-01T08:25:29Z">
    <groups>
      <group name="first">
        <method signature="SkipTest.initialisation()[pri:0, instance:testng.SkipTest@5f341870]" name="initialisation" class="testng.SkipTest"/>
      </group> <!-- first -->
    </groups>
    <test name="Default test" duration-ms="114" started-at="2019-11-01T08:25:29Z" finished-at="2019-11-01T08:25:29Z">
      <class name="testng.SkipTest">
        <test-method status="FAIL" signature="initialisation()[pri:0, instance:testng.SkipTest@5f341870]" name="initialisation" duration-ms="20" started-at="2019-11-01T13:55:29Z" finished-at="2019-11-01T13:55:29Z">
          <exception class="java.lang.AssertionError">
            <message>
              <![CDATA[expected [true] but found [false]]]>
            </message>
            <full-stacktrace>
              <![CDATA[java.lang.AssertionError: expected [true] but found [false]
	at org.testng.Assert.fail(Assert.java:93)
	at org.testng.Assert.failNotEquals(Assert.java:512)
	at org.testng.Assert.assertEqualsImpl(Assert.java:134)
	at org.testng.Assert.assertEquals(Assert.java:115)
	at org.testng.Assert.assertEquals(Assert.java:304)
	at org.testng.Assert.assertEquals(Assert.java:314)
	at testng.SkipTest.initialisation(SkipTest.java:15)
	at sun.reflect.NativeMethodAccessorImpl.invoke0(Native Method)
	at sun.reflect.NativeMethodAccessorImpl.invoke(NativeMethodAccessorImpl.java:62)
	at sun.reflect.DelegatingMethodAccessorImpl.invoke(DelegatingMethodAccessorImpl.java:43)
	at java.lang.reflect.Method.invoke(Method.java:498)
	at org.testng.internal.MethodInvocationHelper.invokeMethod(MethodInvocationHelper.java:108)
	at org.testng.internal.Invoker.invokeMethod(Invoker.java:669)
	at org.testng.internal.Invoker.invokeTestMethod(Invoker.java:877)
	at org.testng.internal.Invoker.invokeTestMethods(Invoker.java:1201)
	at org.testng.internal.TestMethodWorker.invokeTestMethods(TestMethodWorker.java:125)
	at org.testng.internal.TestMethodWorker.run(TestMethodWorker.java:109)
	at org.testng.TestRunner.privateRun(TestRunner.java:776)
	at org.testng.TestRunner.run(TestRunner.java:634)
	at org.testng.SuiteRunner.runTest(SuiteRunner.java:425)
	at org.testng.SuiteRunner.runSequentially(SuiteRunner.java:420)
	at org.testng.SuiteRunner.privateRun(SuiteRunner.java:385)
	at org.testng.SuiteRunner.run(SuiteRunner.java:334)
	at org.testng.SuiteRunnerWorker.runSuite(SuiteRunnerWorker.java:52)
	at org.testng.SuiteRunnerWorker.run(SuiteRunnerWorker.java:86)
	at org.testng.TestNG.runSuitesSequentially(TestNG.java:1318)
	at org.testng.TestNG.runSuitesLocally(TestNG.java:1243)
	at org.testng.TestNG.runSuites(TestNG.java:1161)
	at org.testng.TestNG.run(TestNG.java:1129)
	at org.testng.remote.AbstractRemoteTestNG.run(AbstractRemoteTestNG.java:114)
	at org.testng.remote.RemoteTestNG.initAndRun(RemoteTestNG.java:251)
	at org.testng.remote.RemoteTestNG.main(RemoteTestNG.java:77)
]]>
            </full-stacktrace>
          </exception> <!-- java.lang.AssertionError -->
          <reporter-output>
          </reporter-output>
        </test-method> <!-- initialisation -->
        <test-method status="PASS" signature="close()[pri:0, instance:testng.SkipTest@5f341870]" name="close" is-config="true" duration-ms="1" started-at="2019-11-01T13:55:29Z" finished-at="2019-11-01T13:55:29Z">
          <reporter-output>
          </reporter-output>
        </test-method> <!-- close -->
        <test-method status="SKIP" signature="Login()[pri:0, instance:testng.SkipTest@5f341870]" name="Login" duration-ms="0" started-at="2019-11-01T13:55:29Z" depends-on-methods="testng.SkipTest.initialisation" finished-at="2019-11-01T13:55:29Z">
          <exception class="java.lang.Throwable">
            <message>
              <![CDATA[Method SkipTest.Login()[pri:0, instance:testng.SkipTest@5f341870] depends on not successfully finished methods]]>
            </message>
            <full-stacktrace>
              <![CDATA[java.lang.Throwable: Method SkipTest.Login()[pri:0, instance:testng.SkipTest@5f341870] depends on not successfully finished methods
	at org.testng.internal.Invoker.invokeTestMethods(Invoker.java:1092)
	at org.testng.internal.TestMethodWorker.invokeTestMethods(TestMethodWorker.java:125)
	at org.testng.internal.TestMethodWorker.run(TestMethodWorker.java:109)
	at org.testng.TestRunner.privateRun(TestRunner.java:776)
	at org.testng.TestRunner.run(TestRunner.java:634)
	at org.testng.SuiteRunner.runTest(SuiteRunner.java:425)
	at org.testng.SuiteRunner.runSequentially(SuiteRunner.java:420)
	at org.testng.SuiteRunner.privateRun(SuiteRunner.java:385)
	at org.testng.SuiteRunner.run(SuiteRunner.java:334)
	at org.testng.SuiteRunnerWorker.runSuite(SuiteRunnerWorker.java:52)
	at org.testng.SuiteRunnerWorker.run(SuiteRunnerWorker.java:86)
	at org.testng.TestNG.runSuitesSequentially(TestNG.java:1318)
	at org.testng.TestNG.runSuitesLocally(TestNG.java:1243)
	at org.testng.TestNG.runSuites(TestNG.java:1161)
	at org.testng.TestNG.run(TestNG.java:1129)
	at org.testng.remote.AbstractRemoteTestNG.run(AbstractRemoteTestNG.java:114)
	at org.testng.remote.RemoteTestNG.initAndRun(RemoteTestNG.java:251)
	at org.testng.remote.RemoteTestNG.main(RemoteTestNG.java:77)
]]>
            </full-stacktrace>
          </exception> <!-- java.lang.Throwable -->
          <reporter-output>
          </reporter-output>
        </test-method> <!-- Login -->
        <test-method status="SKIP" signature="Login2()[pri:0, instance:testng.SkipTest@5f341870]" name="Login2" duration-ms="0" depends-on-groups="first" started-at="2019-11-01T13:55:29Z" finished-at="2019-11-01T13:55:29Z">
          <exception class="java.lang.Throwable">
            <message>
              <![CDATA[Method SkipTest.Login2()[pri:0, instance:testng.SkipTest@5f341870] depends on not successfully finished methods in group "first"]]>
            </message>
            <full-stacktrace>
              <![CDATA[java.lang.Throwable: Method SkipTest.Login2()[pri:0, instance:testng.SkipTest@5f341870] depends on not successfully finished methods in group "first"
	at org.testng.internal.Invoker.invokeTestMethods(Invoker.java:1092)
	at org.testng.internal.TestMethodWorker.invokeTestMethods(TestMethodWorker.java:125)
	at org.testng.internal.TestMethodWorker.run(TestMethodWorker.java:109)
	at org.testng.TestRunner.privateRun(TestRunner.java:776)
	at org.testng.TestRunner.run(TestRunner.java:634)
	at org.testng.SuiteRunner.runTest(SuiteRunner.java:425)
	at org.testng.SuiteRunner.runSequentially(SuiteRunner.java:420)
	at org.testng.SuiteRunner.privateRun(SuiteRunner.java:385)
	at org.testng.SuiteRunner.run(SuiteRunner.java:334)
	at org.testng.SuiteRunnerWorker.runSuite(SuiteRunnerWorker.java:52)
	at org.testng.SuiteRunnerWorker.run(SuiteRunnerWorker.java:86)
	at org.testng.TestNG.runSuitesSequentially(TestNG.java:1318)
	at org.testng.TestNG.runSuitesLocally(TestNG.java:1243)
	at org.testng.TestNG.runSuites(TestNG.java:1161)
	at org.testng.TestNG.run(TestNG.java:1129)
	at org.testng.remote.AbstractRemoteTestNG.run(AbstractRemoteTestNG.java:114)
	at org.testng.remote.RemoteTestNG.initAndRun(RemoteTestNG.java:251)
	at org.testng.remote.RemoteTestNG.main(RemoteTestNG.java:77)
]]>
            </full-stacktrace>
          </exception> <!-- java.lang.Throwable -->
          <reporter-output>
          </reporter-output>
        </test-method> <!-- Login2 -->
      </class> <!-- testng.SkipTest -->
    </test> <!-- Default test -->
  </suite> <!-- Default suite -->
</testng-results>
